Workbook

Sheet Overview
A1: Task Management Systems Reference Guide
A3: Research date | B3: 2026-07-15
A4: Platforms compared | B4: 35
A5: Feature criteria | B5: 140
A6: Scoring scale | B6: 0=None/unknown, 1=limited/add-on, 2=native/standard, 3=advanced/native
A7: Scope | B7: Task, project, agile, workflow, enterprise, developer, integration, and AI/agentic capabilities
A8: Caveat | B8: Scores reflect public documentation and product positioning as of the research date; plan-level availability varies.
A9: Source handling | B9: Platform source URLs are included in Platform Profiles and Sources.
A11: Top 10 Overall Scores | B11: Category | C11: Overall | D11: Status | F11: Category | G11: Average Score | H11: Interpretation
A12: ClickUp | B12: General Work Management | C12: 90.7 | D12: Active | F12: Core Work Items | G12: 91.2 | H12: Strong across market
A13: Jira Software | B13: Traditional Issue Tracking / Agile | C13: 90.5 | D13: Active | F13: Planning & Views | G13: 74.1 | H13: Mixed maturity
A14: ServiceNow SPM | B14: Enterprise PPM / Service Workflows | C14: 89 | D14: Active | F14: Agile & Product | G14: 64.3 | H14: Mixed maturity
A15: Wrike | B15: General Work Management / Enterprise | C15: 88.6 | D15: Active | F15: Workflow & Automation | G15: 78.1 | H15: Strong across market
A16: Asana | B16: General Work Management | C16: 87.9 | D16: Active | F16: Collaboration & Knowledge | G16: 73.2 | H16: Mixed maturity
A17: Fibery | B17: Database-Centric / Product OS | C17: 85.4 | D17: Active | F17: Reporting & Analytics | G17: 76.9 | H17: Strong across market
A18: Azure DevOps Boards | B18: Traditional Issue Tracking / Agile | C18: 84.2 | D18: Active | F18: Enterprise & Security | G18: 69.2 | H18: Mixed maturity
A19: GitLab Plan | B19: Developer-Native / DevSecOps | C19: 83.8 | D19: Active | F19: Developer & DevOps | G19: 52.7 | H19: Specialized/limited
A20: IBM Targetprocess | B20: Enterprise Agile / SPM | C20: 83.5 | D20: Active | F20: Integrations & Extensibility | G20: 78.4 | H20: Strong across market
A21: Rally | B21: Enterprise Agile / Value Stream | C21: 83.3 | D21: Active | F21: AI & Agentic | G21: 55.1 | H21: Mixed maturity

Sheet Feature Matrix
A1: Feature Matrix: 35 platforms x 140 criteria
A2: Legend: 0=None/unknown, 1=limited/add-on, 2=native/standard, 3=advanced/native. Use filters to focus by platform or feature area.
A4: Platform | B4: Category | C4: Deployment | D4: Status | E4: Evidence Confidence | F4: Task/work item creation | G4: Issue/bug tracking | H4: Subtasks or child items | I4: Checklists | J4: Recurring tasks | K4: Custom fields | L4: Task templates | M4: Bulk edit | N4: Forms/intake | O4: Attachments | P4: Priority | Q4: Labels/tags | R4: Due dates | S4: Activity history | T4: List/table view | U4: Kanban board | V4: Calendar view | W4: Timeline view | X4: Gantt chart | Y4: Roadmap view | Z4: Milestones | AA4: Dependencies | AB4: Critical path | AC4: Resource planning | AD4: Capacity planning | AE4: Workload view | AF4: Portfolio view | AG4: Program/initiative hierarchy | AH4: Goals/OKRs | AI4: Budget/financial planning | AJ4: Backlog management | AK4: Epics | AL4: User stories | AM4: Sprints/iterations | AN4: Scrum support | AO4: Kanban WIP limits | AP4: Story points | AQ4: Velocity | AR4: Burndown chart | AS4: Release planning | AT4: Product discovery | AU4: Feedback intake/portal | AV4: Prioritization scoring | AW4: Scaled Agile/SAFe | AX4: Custom statuses | AY4: State transition rules | AZ4: Approval workflows | BA4: No-code automations | BB4: Conditional branching | BC4: SLA management | BD4: Request management | BE4: Forms routing | BF4: Recurring automation rules | BG4: Notification rules | BH4: Webhook triggers | BI4: Custom scripts/functions | BJ4: External automation connectors | BK4: Workflow templates | BL4: Incident/service workflows | BM4: Docs/wiki | BN4: Rich text pages | BO4: Real-time co-editing | BP4: Mentions | BQ4: Native chat | BR4: Whiteboards | BS4: Meeting notes | BT4: Decision logs | BU4: File sharing | BV4: Guest/client access | BW4: Discussions/forums | BX4: Knowledge base | BY4: Comment resolution | BZ4: Public sharing | CA4: Dashboards | CB4: Custom reports | CC4: Charts | CD4: Time tracking | CE4: Timesheets | CF4: Estimates | CG4: Cycle time | CH4: Lead time | CI4: Cumulative flow | CJ4: Workload reports | CK4: Portfolio rollups | CL4: Financial reports | CM4: Export | CN4: Saved filters | CO4: SSO/SAML | CP4: SCIM/user provisioning | CQ4: RBAC | CR4: Granular permissions | CS4: Audit logs | CT4: Data residency | CU4: SOC 2 | CV4: ISO 27001 | CW4: HIPAA/regulated support | CX4: Encryption | CY4: Admin console | CZ4: Retention/legal hold | DA4: eDiscovery | DB4: IP allowlisting | DC4: On-prem/self-hosted option | DD4: Published uptime/SLA | DE4: GitHub integration | DF4: GitLab integration | DG4: Bitbucket integration | DH4: Pull request links | DI4: Commit links | DJ4: Branch linking/automation | DK4: CI/CD integration | DL4: Release management | DM4: REST API | DN4: GraphQL API | DO4: CLI or SDK | DP4: Webhooks | DQ4: Repository browsing | DR4: Slack integration | DS4: Microsoft Teams integration | DT4: Email integration | DU4: Google Workspace | DV4: Microsoft 365 | DW4: Zapier | DX4: Make | DY4: n8n | DZ4: Marketplace/apps | EA4: Plugin/extensions | EB4: BI/data export | EC4: AI writing/summarization | ED4: AI task creation | EE4: AI project generation | EF4: AI prioritization | EG4: AI scheduling | EH4: Risk prediction | EI4: AI search/Q&A | EJ4: AI workflow builder | EK4: Configurable AI agents | EL4: Meeting notes to tasks | EM4: Automated status updates | EN4: Human/agent resource planning | EO4: AI governance/admin controls
A5: Jira Software | B5: Traditional Issue Tracking / Agile | C5: SaaS; Data Center | D5: Active | E5: High | F5: 3 | G5: 3 | H5: 3 | I5: 3 | J5: 3 | K5: 3 | L5: 3 | M5: 3 | N5: 3 | O5: 3 | P5: 3 | Q5: 3 | R5: 3 | S5: 3 | T5: 3 | U5: 3 | V5: 3 | W5: 3 | X5: 3 | Y5: 3 | Z5: 3 | AA5: 3 | AB5: 2 | AC5: 3 | AD5: 3 | AE5: 3 | AF5: 3 | AG5: 3 | AH5: 3 | AI5: 1 | AJ5: 3 | AK5: 3 | AL5: 3 | AM5: 3 | AN5: 3 | AO5: 3 | AP5: 3 | AQ5: 3 | AR5: 3 | AS5: 3 | AT5: 3 | AU5: 3 | AV5: 3 | AW5: 2 | AX5: 3 | AY5: 3 | AZ5: 3 | BA5: 3 | BB5: 3 | BC5: 3 | BD5: 3 | BE5: 3 | BF5: 3 | BG5: 3 | BH5: 3 | BI5: 3 | BJ5: 3 | BK5: 3 | BL5: 3 | BM5: 1 | BN5: 2 | BO5: 2 | BP5: 2 | BQ5: 0 | BR5: 1 | BS5: 2 | BT5: 2 | BU5: 2 | BV5: 2 | BW5: 2 | BX5: 2 | BY5: 2 | BZ5: 2 | CA5: 3 | CB5: 3 | CC5: 3 | CD5: 3 | CE5: 3 | CF5: 3 | CG5: 3 | CH5: 3 | CI5: 3 | CJ5: 3 | CK5: 3 | CL5: 3 | CM5: 3 | CN5: 3 | CO5: 3 | CP5: 3 | CQ5: 3 | CR5: 3 | CS5: 3 | CT5: 3 | CU5: 3 | CV5: 3 | CW5: 2 | CX5: 3 | CY5: 3 | CZ5: 2 | DA5: 2 | DB5: 3 | DC5: 3 | DD5: 3 | DE5: 3 | DF5: 3 | DG5: 3 | DH5: 3 | DI5: 3 | DJ5: 3 | DK5: 3 | DL5: 3 | DM5: 3 | DN5: 2 | DO5: 3 | DP5: 3 | DQ5: 3 | DR5: 3 | DS5: 3 | DT5: 3 | DU5: 3 | DV5: 3 | DW5: 3 | DX5: 3 | DY5: 3 | DZ5: 3 | EA5: 3 | EB5: 3 | EC5: 2 | ED5: 2 | EE5: 1 | EF5: 2 | EG5: 2 | EH5: 2 | EI5: 2 | EJ5: 2 | EK5: 2 | EL5: 2 | EM5: 2 | EN5: 1 | EO5: 2
A6: Azure DevOps Boards | B6: Traditional Issue Tracking / Agile | C6: SaaS; Azure DevOps Server | D6: Active | E6: High | F6: 3 | G6: 3 | H6: 3 | I6: 3 | J6: 3 | K6: 3 | L6: 3 | M6: 3 | N6: 3 | O6: 3 | P6: 3 | Q6: 3 | R6: 3 | S6: 3 | T6: 3 | U6: 3 | V6: 3 | W6: 3 | X6: 3 | Y6: 3 | Z6: 3 | AA6: 3 | AB6: 2 | AC6: 3 | AD6: 3 | AE6: 3 | AF6: 3 | AG6: 3 | AH6: 3 | AI6: 1 | AJ6: 3 | AK6: 3 | AL6: 3 | AM6: 3 | AN6: 3 | AO6: 3 | AP6: 3 | AQ6: 3 | AR6: 3 | AS6: 3 | AT6: 3 | AU6: 3 | AV6: 3 | AW6: 2 | AX6: 3 | AY6: 3 | AZ6: 3 | BA6: 3 | BB6: 3 | BC6: 3 | BD6: 3 | BE6: 3 | BF6: 3 | BG6: 3 | BH6: 3 | BI6: 3 | BJ6: 3 | BK6: 3 | BL6: 3 | BM6: 2 | BN6: 2 | BO6: 2 | BP6: 2 | BQ6: 0 | BR6: 0 | BS6: 2 | BT6: 2 | BU6: 2 | BV6: 2 | BW6: 2 | BX6: 2 | BY6: 2 | BZ6: 2 | CA6: 3 | CB6: 3 | CC6: 3 | CD6: 3 | CE6: 3 | CF6: 3 | CG6: 3 | CH6: 3 | CI6: 3 | CJ6: 3 | CK6: 3 | CL6: 3 | CM6: 3 | CN6: 3 | CO6: 3 | CP6: 3 | CQ6: 3 | CR6: 3 | CS6: 3 | CT6: 3 | CU6: 3 | CV6: 3 | CW6: 2 | CX6: 3 | CY6: 3 | CZ6: 2 | DA6: 2 | DB6: 3 | DC6: 3 | DD6: 3 | DE6: 3 | DF6: 3 | DG6: 3 | DH6: 3 | DI6: 3 | DJ6: 3 | DK6: 3 | DL6: 3 | DM6: 3 | DN6: 0 | DO6: 3 | DP6: 3 | DQ6: 3 | DR6: 3 | DS6: 2 | DT6: 3 | DU6: 2 | DV6: 2 | DW6: 2 | DX6: 2 | DY6: 2 | DZ6: 2 | EA6: 2 | EB6: 2 | EC6: 1 | ED6: 1 | EE6: 1 | EF6: 1 | EG6: 1 | EH6: 1 | EI6: 1 | EJ6: 1 | EK6: 0 | EL6: 1 | EM6: 1 | EN6: 0 | EO6: 1
A7: GitHub Projects | B7: Developer-Native | C7: SaaS; GitHub Enterprise Server adjacent | D7: Active | E7: High | F7: 3 | G7: 2 | H7: 2 | I7: 2 | J7: 2 | K7: 2 | L7: 2 | M7: 2 | N7: 2 | O7: 3 | P7: 3 | Q7: 3 | R7: 3 | S7: 2 | T7: 2 | U7: 2 | V7: 2 | W7: 2 | X7: 1 | Y7: 2 | Z7: 2 | AA7: 2 | AB7: 0 | AC7: 0 | AD7: 0 | AE7: 2 | AF7: 2 | AG7: 2 | AH7: 2 | AI7: 0 | AJ7: 2 | AK7: 2 | AL7: 2 | AM7: 2 | AN7: 2 | AO7: 2 | AP7: 2 | AQ7: 2 | AR7: 2 | AS7: 2 | AT7: 2 | AU7: 2 | AV7: 2 | AW7: 1 | AX7: 2 | AY7: 2 | AZ7: 2 | BA7: 2 | BB7: 2 | BC7: 2 | BD7: 2 | BE7: 2 | BF7: 2 | BG7: 2 | BH7: 2 | BI7: 2 | BJ7: 2 | BK7: 2 | BL7: 2 | BM7: 2 | BN7: 2 | BO7: 2 | BP7: 2 | BQ7: 0 | BR7: 2 | BS7: 2 | BT7: 2 | BU7: 2 | BV7: 2 | BW7: 2 | BX7: 2 | BY7: 2 | BZ7: 2 | CA7: 2 | CB7: 2 | CC7: 2 | CD7: 0 | CE7: 2 | CF7: 2 | CG7: 2 | CH7: 2 | CI7: 2 | CJ7: 2 | CK7: 2 | CL7: 2 | CM7: 2 | CN7: 2 | CO7: 2 | CP7: 2 | CQ7: 2 | CR7: 2 | CS7: 2 | CT7: 2 | CU7: 2 | CV7: 2 | CW7: 1 | CX7: 2 | CY7: 2 | CZ7: 1 | DA7: 1 | DB7: 2 | DC7: 2 | DD7: 2 | DE7: 3 | DF7: 3 | DG7: 3 | DH7: 3 | DI7: 3 | DJ7: 3 | DK7: 3 | DL7: 3 | DM7: 3 | DN7: 3 | DO7: 3 | DP7: 3 | DQ7: 3 | DR7: 3 | DS7: 3 | DT7: 3 | DU7: 3 | DV7: 3 | DW7: 3 | DX7: 3 | DY7: 3 | DZ7: 3 | EA7: 3 | EB7: 3 | EC7: 2 | ED7: 2 | EE7: 2 | EF7: 2 | EG7: 2 | EH7: 2 | EI7: 2 | EJ7: 2 | EK7: 1 | EL7: 2 | EM7: 2 | EN7: 1 | EO7: 2
A8: Linear | B8: Developer-Native | C8: SaaS | D8: Active | E8: High | F8: 3 | G8: 3 | H8: 3 | I8: 3 | J8: 3 | K8: 3 | L8: 3 | M8: 3 | N8: 3 | O8: 3 | P8: 3 | Q8: 3 | R8: 3 | S8: 3 | T8: 2 | U8: 2 | V8: 2 | W8: 2 | X8: 1 | Y8: 2 | Z8: 2 | AA8: 2 | AB8: 0 | AC8: 1 | AD8: 2 | AE8: 2 | AF8: 2 | AG8: 2 | AH8: 2 | AI8: 0 | AJ8: 3 | AK8: 3 | AL8: 3 | AM8: 3 | AN8: 3 | AO8: 3 | AP8: 3 | AQ8: 3 | AR8: 3 | AS8: 3 | AT8: 3 | AU8: 3 | AV8: 3 | AW8: 2 | AX8: 2 | AY8: 2 | AZ8: 2 | BA8: 2 | BB8: 2 | BC8: 2 | BD8: 2 | BE8: 2 | BF8: 2 | BG8: 2 | BH8: 2 | BI8: 2 | BJ8: 2 | BK8: 2 | BL8: 2 | BM8: 2 | BN8: 2 | BO8: 2 | BP8: 2 | BQ8: 2 | BR8: 0 | BS8: 2 | BT8: 2 | BU8: 2 | BV8: 2 | BW8: 2 | BX8: 2 | BY8: 2 | BZ8: 2 | CA8: 2 | CB8: 2 | CC8: 2 | CD8: 0 | CE8: 2 | CF8: 2 | CG8: 2 | CH8: 2 | CI8: 2 | CJ8: 2 | CK8: 2 | CL8: 2 | CM8: 2 | CN8: 2 | CO8: 2 | CP8: 2 | CQ8: 2 | CR8: 2 | CS8: 2 | CT8: 2 | CU8: 2 | CV8: 2 | CW8: 1 | CX8: 2 | CY8: 2 | CZ8: 1 | DA8: 1 | DB8: 2 | DC8: 2 | DD8: 2 | DE8: 3 | DF8: 3 | DG8: 3 | DH8: 3 | DI8: 3 | DJ8: 3 | DK8: 3 | DL8: 3 | DM8: 3 | DN8: 3 | DO8: 3 | DP8: 3 | DQ8: 3 | DR8: 3 | DS8: 3 | DT8: 3 | DU8: 3 | DV8: 3 | DW8: 3 | DX8: 3 | DY8: 3 | DZ8: 3 | EA8: 3 | EB8: 3 | EC8: 3 | ED8: 3 | EE8: 3 | EF8: 3 | EG8: 1 | EH8: 3 | EI8: 3 | EJ8: 3 | EK8: 2 | EL8: 3 | EM8: 3 | EN8: 2 | EO8: 3
A9: GitLab Plan | B9: Developer-Native / DevSecOps | C9: SaaS; self-managed; dedicated | D9: Active | E9: High | F9: 3 | G9: 3 | H9: 3 | I9: 3 | J9: 3 | K9: 3 | L9: 3 | M9: 3 | N9: 3 | O9: 3 | P9: 3 | Q9: 3 | R9: 3 | S9: 3 | T9: 3 | U9: 3 | V9: 3 | W9: 3 | X9: 3 | Y9: 3 | Z9: 3 | AA9: 3 | AB9: 1 | AC9: 1 | AD9: 1 | AE9: 3 | AF9: 3 | AG9: 3 | AH9: 3 | AI9: 0 | AJ9: 3 | AK9: 3 | AL9: 3 | AM9: 3 | AN9: 3 | AO9: 3 | AP9: 3 | AQ9: 3 | AR9: 3 | AS9: 3 | AT9: 3 | AU9: 3 | AV9: 3 | AW9: 2 | AX9: 2 | AY9: 2 | AZ9: 2 | BA9: 2 | BB9: 2 | BC9: 2 | BD9: 2 | BE9: 2 | BF9: 2 | BG9: 2 | BH9: 2 | BI9: 2 | BJ9: 2 | BK9: 2 | BL9: 2 | BM9: 2 | BN9: 2 | BO9: 2 | BP9: 2 | BQ9: 0 | BR9: 2 | BS9: 2 | BT9: 2 | BU9: 2 | BV9: 2 | BW9: 2 | BX9: 2 | BY9: 2 | BZ9: 2 | CA9: 3 | CB9: 3 | CC9: 3 | CD9: 3 | CE9: 3 | CF9: 3 | CG9: 3 | CH9: 3 | CI9: 3 | CJ9: 3 | CK9: 3 | CL9: 3 | CM9: 3 | CN9: 3 | CO9: 3 | CP9: 3 | CQ9: 3 | CR9: 3 | CS9: 3 | CT9: 3 | CU9: 3 | CV9: 3 | CW9: 2 | CX9: 3 | CY9: 3 | CZ9: 2 | DA9: 2 | DB9: 3 | DC9: 3 | DD9: 3 | DE9: 3 | DF9: 3 | DG9: 3 | DH9: 3 | DI9: 3 | DJ9: 3 | DK9: 3 | DL9: 3 | DM9: 3 | DN9: 3 | DO9: 3 | DP9: 3 | DQ9: 3 | DR9: 3 | DS9: 2 | DT9: 3 | DU9: 2 | DV9: 2 | DW9: 2 | DX9: 2 | DY9: 2 | DZ9: 2 | EA9: 2 | EB9: 2 | EC9: 2 | ED9: 2 | EE9: 2 | EF9: 2 | EG9: 2 | EH9: 2 | EI9: 2 | EJ9: 2 | EK9: 1 | EL9: 2 | EM9: 2 | EN9: 1 | EO9: 2
A10: Asana | B10: General Work Management | C10: SaaS | D10: Active | E10: High | F10: 3 | G10: 3 | H10: 3 | I10: 3 | J10: 3 | K10: 3 | L10: 3 | M10: 3 | N10: 3 | O10: 3 | P10: 3 | Q10: 3 | R10: 3 | S10: 3 | T10: 3 | U10: 3 | V10: 3 | W10: 3 | X10: 2 | Y10: 3 | Z10: 3 | AA10: 3 | AB10: 2 | AC10: 3 | AD10: 3 | AE10: 3 | AF10: 3 | AG10: 3 | AH10: 3 | AI10: 2 | AJ10: 2 | AK10: 2 | AL10: 2 | AM10: 2 | AN10: 1 | AO10: 2 | AP10: 1 | AQ10: 1 | AR10: 2 | AS10: 2 | AT10: 2 | AU10: 2 | AV10: 2 | AW10: 1 | AX10: 3 | AY10: 3 | AZ10: 3 | BA10: 3 | BB10: 3 | BC10: 3 | BD10: 3 | BE10: 3 | BF10: 3 | BG10: 3 | BH10: 3 | BI10: 3 | BJ10: 3 | BK10: 3 | BL10: 3 | BM10: 3 | BN10: 3 | BO10: 3 | BP10: 3 | BQ10: 3 | BR10: 3 | BS10: 3 | BT10: 3 | BU10: 3 | BV10: 3 | BW10: 3 | BX10: 3 | BY10: 3 | BZ10: 3 | CA10: 3 | CB10: 3 | CC10: 3 | CD10: 3 | CE10: 3 | CF10: 3 | CG10: 3 | CH10: 3 | CI10: 3 | CJ10: 3 | CK10: 3 | CL10: 3 | CM10: 3 | CN10: 3 | CO10: 3 | CP10: 3 | CQ10: 3 | CR10: 3 | CS10: 3 | CT10: 3 | CU10: 3 | CV10: 3 | CW10: 2 | CX10: 3 | CY10: 3 | CZ10: 2 | DA10: 2 | DB10: 3 | DC10: 3 | DD10: 3 | DE10: 1 | DF10: 1 | DG10: 1 | DH10: 1 | DI10: 1 | DJ10: 1 | DK10: 1 | DL10: 1 | DM10: 2 | DN10: 0 | DO10: 1 | DP10: 1 | DQ10: 0 | DR10: 3 | DS10: 3 | DT10: 3 | DU10: 3 | DV10: 3 | DW10: 3 | DX10: 3 | DY10: 3 | DZ10: 3 | EA10: 3 | EB10: 3 | EC10: 3 | ED10: 3 | EE10: 3 | EF10: 3 | EG10: 3 | EH10: 3 | EI10: 3 | EJ10: 3 | EK10: 3 | EL10: 3 | EM10: 3 | EN10: 2 | EO10: 3
A11: monday work management | B11: General Work Management | C11: SaaS | D11: Active | E11: Medium | F11: 3 | G11: 3 | H11: 3 | I11: 3 | J11: 3 | K11: 3 | L11: 3 | M11: 3 | N11: 3 | O11: 3 | P11: 3 | Q11: 3 | R11: 3 | S11: 3 | T11: 3 | U11: 3 | V11: 3 | W11: 3 | X11: 3 | Y11: 3 | Z11: 3 | AA11: 3 | AB11: 2 | AC11: 3 | AD11: 3 | AE11: 3 | AF11: 3 | AG11: 3 | AH11: 3 | AI11: 2 | AJ11: 2 | AK11: 2 | AL11: 2 | AM11: 2 | AN11: 1 | AO11: 2 | AP11: 2 | AQ11: 1 | AR11: 1 | AS11: 2 | AT11: 2 | AU11: 2 | AV11: 2 | AW11: 1 | AX11: 3 | AY11: 3 | AZ11: 3 | BA11: 3 | BB11: 3 | BC11: 3 | BD11: 3 | BE11: 3 | BF11: 3 | BG11: 3 | BH11: 3 | BI11: 3 | BJ11: 3 | BK11: 3 | BL11: 3 | BM11: 2 | BN11: 2 | BO11: 2 | BP11: 2 | BQ11: 2 | BR11: 2 | BS11: 2 | BT11: 2 | BU11: 2 | BV11: 2 | BW11: 2 | BX11: 2 | BY11: 2 | BZ11: 2 | CA11: 3 | CB11: 3 | CC11: 3 | CD11: 3 | CE11: 3 | CF11: 3 | CG11: 3 | CH11: 3 | CI11: 3 | CJ11: 3 | CK11: 3 | CL11: 3 | CM11: 3 | CN11: 3 | CO11: 3 | CP11: 3 | CQ11: 3 | CR11: 3 | CS11: 3 | CT11: 3 | CU11: 3 | CV11: 3 | CW11: 2 | CX11: 3 | CY11: 3 | CZ11: 2 | DA11: 2 | DB11: 3 | DC11: 3 | DD11: 3 | DE11: 1 | DF11: 1 | DG11: 1 | DH11: 1 | DI11: 1 | DJ11: 1 | DK11: 1 | DL11: 1 | DM11: 2 | DN11: 3 | DO11: 1 | DP11: 1 | DQ11: 0 | DR11: 3 | DS11: 3 | DT11: 3 | DU11: 3 | DV11: 3 | DW11: 3 | DX11: 3 | DY11: 3 | DZ11: 3 | EA11: 3 | EB11: 3 | EC11: 2 | ED11: 2 | EE11: 2 | EF11: 2 | EG11: 2 | EH11: 2 | EI11: 2 | EJ11: 2 | EK11: 1 | EL11: 2 | EM11: 2 | EN11: 1 | EO11: 2
A12: ClickUp | B12: General Work Management | C12: SaaS | D12: Active | E12: High | F12: 3 | G12: 3 | H12: 3 | I12: 3 | J12: 3 | K12: 3 | L12: 3 | M12: 3 | N12: 3 | O12: 3 | P12: 3 | Q12: 3 | R12: 3 | S12: 3 | T12: 3 | U12: 3 | V12: 3 | W12: 3 | X12: 3 | Y12: 3 | Z12: 3 | AA12: 3 | AB12: 2 | AC12: 3 | AD12: 3 | AE12: 3 | AF12: 3 | AG12: 3 | AH12: 3 | AI12: 2 | AJ12: 3 | AK12: 3 | AL12: 3 | AM12: 3 | AN12: 3 | AO12: 3 | AP12: 3 | AQ12: 3 | AR12: 3 | AS12: 3 | AT12: 3 | AU12: 3 | AV12: 3 | AW12: 1 | AX12: 3 | AY12: 3 | AZ12: 3 | BA12: 3 | BB12: 3 | BC12: 3 | BD12: 3 | BE12: 3 | BF12: 3 | BG12: 3 | BH12: 3 | BI12: 3 | BJ12: 3 | BK12: 3 | BL12: 3 | BM12: 3 | BN12: 3 | BO12: 3 | BP12: 3 | BQ12: 3 | BR12: 3 | BS12: 3 | BT12: 3 | BU12: 3 | BV12: 3 | BW12: 3 | BX12: 3 | BY12: 3 | BZ12: 3 | CA12: 3 | CB12: 3 | CC12: 3 | CD12: 3 | CE12: 3 | CF12: 3 | CG12: 3 | CH12: 3 | CI12: 3 | CJ12: 3 | CK12: 3 | CL12: 3 | CM12: 3 | CN12: 3 | CO12: 2 | CP12: 2 | CQ12: 2 | CR12: 2 | CS12: 2 | CT12: 2 | CU12: 2 | CV12: 2 | CW12: 1 | CX12: 2 | CY12: 2 | CZ12: 1 | DA12: 1 | DB12: 2 | DC12: 2 | DD12: 2 | DE12: 2 | DF12: 2 | DG12: 2 | DH12: 2 | DI12: 2 | DJ12: 2 | DK12: 2 | DL12: 2 | DM12: 3 | DN12: 0 | DO12: 2 | DP12: 2 | DQ12: 0 | DR12: 3 | DS12: 3 | DT12: 3 | DU12: 3 | DV12: 3 | DW12: 3 | DX12: 3 | DY12: 3 | DZ12: 3 | EA12: 3 | EB12: 3 | EC12: 3 | ED12: 3 | EE12: 3 | EF12: 3 | EG12: 3 | EH12: 3 | EI12: 3 | EJ12: 3 | EK12: 2 | EL12: 3 | EM12: 3 | EN12: 2 | EO12: 3
A13: Trello | B13: Kanban / Lightweight Work Management | C13: SaaS | D13: Active | E13: High | F13: 3 | G13: 2 | H13: 2 | I13: 2 | J13: 2 | K13: 2 | L13: 2 | M13: 2 | N13: 2 | O13: 3 | P13: 3 | Q13: 3 | R13: 3 | S13: 2 | T13: 1 | U13: 3 | V13: 1 | W13: 1 | X13: 1 | Y13: 1 | Z13: 1 | AA13: 1 | AB13: 0 | AC13: 0 | AD13: 0 | AE13: 1 | AF13: 0 | AG13: 1 | AH13: 1 | AI13: 0 | AJ13: 1 | AK13: 1 | AL13: 1 | AM13: 1 | AN13: 1 | AO13: 1 | AP13: 0 | AQ13: 0 | AR13: 0 | AS13: 1 | AT13: 1 | AU13: 1 | AV13: 1 | AW13: 0 | AX13: 2 | AY13: 2 | AZ13: 2 | BA13: 2 | BB13: 2 | BC13: 2 | BD13: 2 | BE13: 2 | BF13: 2 | BG13: 2 | BH13: 2 | BI13: 2 | BJ13: 2 | BK13: 2 | BL13: 2 | BM13: 2 | BN13: 2 | BO13: 2 | BP13: 2 | BQ13: 2 | BR13: 2 | BS13: 2 | BT13: 2 | BU13: 2 | BV13: 2 | BW13: 2 | BX13: 2 | BY13: 2 | BZ13: 2 | CA13: 1 | CB13: 1 | CC13: 1 | CD13: 1 | CE13: 1 | CF13: 1 | CG13: 1 | CH13: 1 | CI13: 1 | CJ13: 1 | CK13: 1 | CL13: 1 | CM13: 1 | CN13: 1 | CO13: 2 | CP13: 2 | CQ13: 2 | CR13: 2 | CS13: 2 | CT13: 2 | CU13: 2 | CV13: 2 | CW13: 1 | CX13: 2 | CY13: 2 | CZ13: 1 | DA13: 1 | DB13: 2 | DC13: 2 | DD13: 2 | DE13: 1 | DF13: 1 | DG13: 1 | DH13: 1 | DI13: 1 | DJ13: 1 | DK13: 1 | DL13: 1 | DM13: 2 | DN13: 0 | DO13: 1 | DP13: 1 | DQ13: 1 | DR13: 3 | DS13: 3 | DT13: 3 | DU13: 3 | DV13: 3 | DW13: 3 | DX13: 3 | DY13: 3 | DZ13: 3 | EA13: 3 | EB13: 3 | EC13: 1 | ED13: 1 | EE13: 1 | EF13: 1 | EG13: 1 | EH13: 1 | EI13: 1 | EJ13: 1 | EK13: 0 | EL13: 1 | EM13: 1 | EN13: 0 | EO13: 1
A14: Wrike | B14: General Work Management / Enterprise | C14: SaaS | D14: Active | E14: High | F14: 3 | G14: 3 | H14: 3 | I14: 3 | J14: 3 | K14: 3 | L14: 3 | M14: 3 | N14: 3 | O14: 3 | P14: 3 | Q14: 3 | R14: 3 | S14: 3 | T14: 3 | U14: 3 | V14: 3 | W14: 3 | X14: 3 | Y14: 3 | Z14: 3 | AA14: 3 | AB14: 2 | AC14: 3 | AD14: 3 | AE14: 3 | AF14: 3 | AG14: 3 | AH14: 3 | AI14: 2 | AJ14: 2 | AK14: 2 | AL14: 2 | AM14: 2 | AN14: 2 | AO14: 2 | AP14: 2 | AQ14: 2 | AR14: 2 | AS14: 2 | AT14: 2 | AU14: 2 | AV14: 2 | AW14: 1 | AX14: 3 | AY14: 3 | AZ14: 3 | BA14: 3 | BB14: 3 | BC14: 3 | BD14: 3 | BE14: 3 | BF14: 3 | BG14: 3 | BH14: 3 | BI14: 3 | BJ14: 3 | BK14: 3 | BL14: 3 | BM14: 3 | BN14: 3 | BO14: 3 | BP14: 3 | BQ14: 3 | BR14: 3 | BS14: 3 | BT14: 3 | BU14: 3 | BV14: 3 | BW14: 3 | BX14: 3 | BY14: 3 | BZ14: 3 | CA14: 3 | CB14: 3 | CC14: 3 | CD14: 3 | CE14: 3 | CF14: 3 | CG14: 3 | CH14: 3 | CI14: 3 | CJ14: 3 | CK14: 3 | CL14: 3 | CM14: 3 | CN14: 3 | CO14: 3 | CP14: 3 | CQ14: 3 | CR14: 3 | CS14: 3 | CT14: 3 | CU14: 3 | CV14: 3 | CW14: 2 | CX14: 3 | CY14: 3 | CZ14: 2 | DA14: 2 | DB14: 3 | DC14: 3 | DD14: 3 | DE14: 1 | DF14: 1 | DG14: 1 | DH14: 1 | DI14: 1 | DJ14: 1 | DK14: 1 | DL14: 1 | DM14: 2 | DN14: 0 | DO14: 1 | DP14: 1 | DQ14: 0 | DR14: 3 | DS14: 3 | DT14: 3 | DU14: 3 | DV14: 3 | DW14: 3 | DX14: 3 | DY14: 3 | DZ14: 3 | EA14: 3 | EB14: 3 | EC14: 3 | ED14: 3 | EE14: 3 | EF14: 3 | EG14: 3 | EH14: 3 | EI14: 3 | EJ14: 3 | EK14: 2 | EL14: 3 | EM14: 3 | EN14: 2 | EO14: 3
A15: Smartsheet | B15: Work Management / PMO | C15: SaaS | D15: Active | E15: High | F15: 3 | G15: 3 | H15: 3 | I15: 3 | J15: 3 | K15: 3 | L15: 3 | M15: 3 | N15: 3 | O15: 3 | P15: 3 | Q15: 3 | R15: 3 | S15: 3 | T15: 3 | U15: 3 | V15: 3 | W15: 3 | X15: 3 | Y15: 3 | Z15: 3 | AA15: 3 | AB15: 2 | AC15: 3 | AD15: 3 | AE15: 3 | AF15: 3 | AG15: 3 | AH15: 3 | AI15: 2 | AJ15: 2 | AK15: 2 | AL15: 2 | AM15: 2 | AN15: 1 | AO15: 1 | AP15: 1 | AQ15: 2 | AR15: 2 | AS15: 2 | AT15: 2 | AU15: 2 | AV15: 2 | AW15: 1 | AX15: 3 | AY15: 3 | AZ15: 3 | BA15: 3 | BB15: 3 | BC15: 3 | BD15: 3 | BE15: 3 | BF15: 3 | BG15: 3 | BH15: 3 | BI15: 3 | BJ15: 3 | BK15: 3 | BL15: 3 | BM15: 2 | BN15: 2 | BO15: 2 | BP15: 2 | BQ15: 2 | BR15: 1 | BS15: 2 | BT15: 2 | BU15: 2 | BV15: 2 | BW15: 2 | BX15: 2 | BY15: 2 | BZ15: 2 | CA15: 3 | CB15: 3 | CC15: 3 | CD15: 3 | CE15: 3 | CF15: 3 | CG15: 3 | CH15: 3 | CI15: 3 | CJ15: 3 | CK15: 3 | CL15: 3 | CM15: 3 | CN15: 3 | CO15: 3 | CP15: 3 | CQ15: 3 | CR15: 3 | CS15: 3 | CT15: 3 | CU15: 3 | CV15: 3 | CW15: 2 | CX15: 3 | CY15: 3 | CZ15: 2 | DA15: 2 | DB15: 3 | DC15: 3 | DD15: 3 | DE15: 1 | DF15: 1 | DG15: 1 | DH15: 1 | DI15: 1 | DJ15: 1 | DK15: 1 | DL15: 1 | DM15: 2 | DN15: 0 | DO15: 1 | DP15: 1 | DQ15: 0 | DR15: 3 | DS15: 3 | DT15: 3 | DU15: 3 | DV15: 3 | DW15: 3 | DX15: 3 | DY15: 3 | DZ15: 3 | EA15: 3 | EB15: 3 | EC15: 2 | ED15: 2 | EE15: 2 | EF15: 2 | EG15: 2 | EH15: 2 | EI15: 2 | EJ15: 2 | EK15: 1 | EL15: 2 | EM15: 2 | EN15: 1 | EO15: 2
A16: Airtable | B16: Database-Centric Work Platform | C16: SaaS | D16: Active | E16: High | F16: 3 | G16: 3 | H16: 3 | I16: 3 | J16: 3 | K16: 3 | L16: 3 | M16: 3 | N16: 3 | O16: 3 | P16: 3 | Q16: 3 | R16: 3 | S16: 3 | T16: 2 | U16: 2 | V16: 2 | W16: 2 | X16: 1 | Y16: 2 | Z16: 2 | AA16: 2 | AB16: 0 | AC16: 2 | AD16: 2 | AE16: 2 | AF16: 2 | AG16: 2 | AH16: 2 | AI16: 1 | AJ16: 1 | AK16: 1 | AL16: 1 | AM16: 1 | AN16: 1 | AO16: 1 | AP16: 1 | AQ16: 1 | AR16: 0 | AS16: 1 | AT16: 1 | AU16: 1 | AV16: 1 | AW16: 0 | AX16: 3 | AY16: 3 | AZ16: 3 | BA16: 3 | BB16: 3 | BC16: 3 | BD16: 3 | BE16: 3 | BF16: 3 | BG16: 3 | BH16: 3 | BI16: 3 | BJ16: 3 | BK16: 3 | BL16: 3 | BM16: 2 | BN16: 2 | BO16: 2 | BP16: 2 | BQ16: 2 | BR16: 2 | BS16: 2 | BT16: 2 | BU16: 2 | BV16: 2 | BW16: 2 | BX16: 2 | BY16: 2 | BZ16: 2 | CA16: 2 | CB16: 2 | CC16: 2 | CD16: 1 | CE16: 2 | CF16: 2 | CG16: 2 | CH16: 2 | CI16: 2 | CJ16: 2 | CK16: 2 | CL16: 2 | CM16: 2 | CN16: 2 | CO16: 3 | CP16: 3 | CQ16: 3 | CR16: 3 | CS16: 3 | CT16: 3 | CU16: 3 | CV16: 3 | CW16: 2 | CX16: 3 | CY16: 3 | CZ16: 2 | DA16: 2 | DB16: 3 | DC16: 3 | DD16: 3 | DE16: 1 | DF16: 1 | DG16: 1 | DH16: 1 | DI16: 1 | DJ16: 1 | DK16: 1 | DL16: 1 | DM16: 2 | DN16: 0 | DO16: 1 | DP16: 1 | DQ16: 1 | DR16: 3 | DS16: 3 | DT16: 3 | DU16: 3 | DV16: 3 | DW16: 3 | DX16: 3 | DY16: 3 | DZ16: 3 | EA16: 3 | EB16: 3 | EC16: 3 | ED16: 3 | EE16: 3 | EF16: 3 | EG16: 3 | EH16: 3 | EI16: 3 | EJ16: 3 | EK16: 2 | EL16: 3 | EM16: 3 | EN16: 2 | EO16: 3
... A39: Height | B39: AI-Native / Discontinued | C39: SaaS | D39: Discontinued Sep 2025 | E39: Medium | F39: 2 | G39: 2 | H39: 2 | I39: 2 | J39: 2 | K39: 2 | L39: 2 | M39: 2 | N39: 2 | O39: 2 | P39: 2 | Q39: 2 | R39: 2 | S39: 2 | T39: 2 | U39: 2 | V39: 2 | W39: 2 | X39: 2 | Y39: 2 | Z39: 2 | AA39: 2 | AB39: 1 | AC39: 2 | AD39: 2 | AE39: 2 | AF39: 2 | AG39: 2 | AH39: 2 | AI39: 1 | AJ39: 2 | AK39: 2 | AL39: 2 | AM39: 2 | AN39: 2 | AO39: 2 | AP39: 2 | AQ39: 2 | AR39: 2 | AS39: 2 | AT39: 2 | AU39: 2 | AV39: 2 | AW39: 1 | AX39: 2 | AY39: 2 | AZ39: 2 | BA39: 2 | BB39: 2 | BC39: 2 | BD39: 2 | BE39: 2 | BF39: 2 | BG39: 2 | BH39: 2 | BI39: 2 | BJ39: 2 | BK39: 2 | BL39: 2 | BM39: 2 | BN39: 2 | BO39: 2 | BP39: 2 | BQ39: 2 | BR39: 2 | BS39: 2 | BT39: 2 | BU39: 2 | BV39: 2 | BW39: 2 | BX39: 2 | BY39: 2 | BZ39: 2 | CA39: 1 | CB39: 1 | CC39: 1 | CD39: 1 | CE39: 1 | CF39: 1 | CG39: 1 | CH39: 1 | CI39: 1 | CJ39: 1 | CK39: 1 | CL39: 1 | CM39: 1 | CN39: 1 | CO39: 1 | CP39: 1 | CQ39: 1 | CR39: 1 | CS39: 1 | CT39: 1 | CU39: 1 | CV39: 1 | CW39: 0 | CX39: 1 | CY39: 1 | CZ39: 0 | DA39: 0 | DB39: 1 | DC39: 1 | DD39: 0 | DE39: 2 | DF39: 2 | DG39: 2 | DH39: 2 | DI39: 2 | DJ39: 2 | DK39: 2 | DL39: 2 | DM39: 2 | DN39: 1 | DO39: 2 | DP39: 2 | DQ39: 2 | DR39: 2 | DS39: 1 | DT39: 2 | DU39: 1 | DV39: 1 | DW39: 1 | DX39: 1 | DY39: 1 | DZ39: 1 | EA39: 1 | EB39: 1 | EC39: 3 | ED39: 3 | EE39: 2 | EF39: 3 | EG39: 2 | EH39: 2 | EI39: 2 | EJ39: 2 | EK39: 2 | EL39: 2 | EM39: 3 | EN39: 2 | EO39: 2

Sheet Platform Profiles
A1: Platform Profiles
A3: Platform | B3: Category | C3: Status | D3: Deployment | E3: Pricing model | F3: Best fit | G3: Strengths | H3: Limitations | I3: Primary source URLs
A4: Jira Software | B4: Traditional Issue Tracking / Agile | C4: Active | D4: SaaS; Data Center | E4: Free; paid per user; enterprise | F4: Software teams needing mature agile tracking, workflows, automation, and governance. | G4: Deep workflow customization, agile reporting, marketplace, enterprise controls, developer ecosystem. | H4: Configuration can become complex; advanced portfolio features often require Premium/Enterprise or Atlassian ecosystem products. | I4: https://www.atlassian.com/software/jira/features https://www.atlassian.com/roadmap/cloud https://confluence.atlassian.com/cloud/blog
A5: Azure DevOps Boards | B5: Traditional Issue Tracking / Agile | C5: Active | D5: SaaS; Azure DevOps Server | E5: Free tier; Basic per user; server licensing | F5: Microsoft-centric engineering teams needing traceability across work, repos, pipelines, and tests. | G5: Strong work item model, backlogs, boards, sprints, Delivery Plans, dashboards, and DevOps traceability. | H5: Less polished for non-engineering work; AI features arrive mainly through broader Microsoft/GitHub ecosystem. | I5: https://azure.microsoft.com/en-us/products/devops/boards https://learn.microsoft.com/en-us/azure/devops/boards/get-started/what-is-azure-boards?view=azure-devops https://learn.microsoft.com/en-us/azure/devops/boards/work-items/about-work-items?view=azure-devops
A6: GitHub Projects | B6: Developer-Native | C6: Active | D6: SaaS; GitHub Enterprise Server adjacent | E6: Included with GitHub plans; Enterprise features by plan | F6: Developer teams already living in GitHub issues, pull requests, and Actions. | G6: Tight issue/PR linkage, flexible table/board/roadmap views, code-native automation, broad API surface. | H6: Lighter than dedicated PM tools for portfolio, capacity, resourcing, workflow approvals, and reporting. | I6: https://github.com/features/issues https://docs.github.com/issues/planning-and-tracking-with-projects/learning-about-projects/about-projects https://docs.github.com/en/issues/planning-and-tracking-with-projects
A7: Linear | B7: Developer-Native | C7: Active | D7: SaaS | E7: Free; paid per user; enterprise | F7: Product engineering teams that value speed, opinionated issue tracking, cycles, roadmaps, and AI-assisted product work. | G7: Fast UI, cycles, projects, initiatives, strong GitHub/Slack workflow, modern AI positioning. | H7: Less customizable and less enterprise-PPM oriented than Jira, ServiceNow, or Planview. | I7: https://linear.app/ https://linear.app/plan https://linear.app/integrations
A8: GitLab Plan | B8: Developer-Native / DevSecOps | C8: Active | D8: SaaS; self-managed; dedicated | E8: Free; Premium; Ultimate | F8: Teams using GitLab as a single DevSecOps platform and wanting planning close to source, CI, security, and releases. | G8: Issues, epics, milestones, boards, roadmaps, releases, CI/CD and security context in one platform. | H8: Project-management UX is less flexible for broad business teams than work management platforms. | I8: https://docs.gitlab.com/user/group/epics/ https://docs.gitlab.com/user/group/roadmap/ https://about.gitlab.com/features/
A9: Asana | B9: General Work Management | C9: Active | D9: SaaS | E9: Free; paid tiers; Enterprise | F9: Cross-functional teams needing goals, portfolios, structured workflows, automation, and AI work orchestration. | G9: Excellent work graph, goals, portfolios, automation, reporting, forms, approvals, and AI Studio. | H9: Less developer-native than Jira/Linear/GitHub; advanced security and portfolio features vary by plan. | I9: https://asana.com/features https://asana.com/product/ai https://help.asana.com/s/article/learn-about-asana-advanced-features
A10: monday work management | B10: General Work Management | C10: Active | D10: SaaS | E10: Free/Basic/Standard/Pro/Enterprise | F10: Business teams needing visual, configurable boards, automations, dashboards, and app-like workflows. | G10: Flexible boards, automations, dashboards, templates, integrations, and broad business use cases. | H10: Engineering-specific agile and DevOps depth often requires integrations or monday dev. | I10: https://monday.com/ https://monday.com/work-management https://monday.com/features/automations
A11: ClickUp | B11: General Work Management | C11: Active | D11: SaaS | E11: Free; paid per user; Enterprise | F11: Teams wanting many work modes in one product: tasks, docs, goals, whiteboards, dashboards, chat, and AI. | G11: Broad feature coverage, docs/whiteboards/chat, hierarchy, dashboards, automations, ClickUp Brain. | H11: Breadth can create complexity; some advanced features vary by plan. | I11: https://clickup.com/ https://clickup.com/features https://clickup.com/blog/ai-workflow-automation/
A12: Trello | B12: Kanban / Lightweight Work Management | C12: Active | D12: SaaS | E12: Free; Standard; Premium; Enterprise | F12: Simple visual Kanban workflows and small-team coordination. | G12: Simple boards/cards, Power-Ups marketplace, Butler automation, accessible UX. | H12: Limited native portfolio, reporting, dependencies, resource planning, and agile metrics. | I12: https://trello.com/power-ups https://trello.com/pricing https://trello.com/enterprise
A13: Wrike | B13: General Work Management / Enterprise | C13: Active | D13: SaaS | E13: Free; Team; Business; Enterprise; Pinnacle | F13: Enterprise marketing, operations, and services teams needing resource management, reporting, and automation. | G13: Gantt, dashboards, analytics, resource planning, request forms, approvals, AI risk and work intelligence. | H13: Engineering agile and DevOps workflows are less native than developer-focused tools. | I13: https://www.wrike.com/features/ https://www.wrike.com/ https://www.wrike.com/features/work-intelligence/
A14: Smartsheet | B14: Work Management / PMO | C14: Active | D14: SaaS | E14: Pro; Business; Enterprise; advanced add-ons | F14: PMOs and business teams that like spreadsheet-like control with dashboards, automations, and portfolio reporting. | G14: Sheets, forms, reports, dashboards, resource management, portfolio management, automation, enterprise controls. | H14: Less opinionated for software delivery; deeper agile product workflows usually need configuration or integrations. | I14: https://www.smartsheet.com/platform/features https://www.smartsheet.com/solutions/project-management https://www.smartsheet.com/
... A38: Height | B38: AI-Native / Discontinued | C38: Discontinued Sep 2025 | D38: SaaS | E38: No longer available | F38: Historical reference for autonomous project management ideas: bug triage, backlog pruning, and spec updates. | G38: Pioneered autonomous project-management positioning for product teams. | H38: Discontinued; not suitable for new adoption. | I38: https://www.businesswire.com/news/home/20241008197812/en/Height.app-Unveils-First-Ever-Autonomous-Project-Collaboration-Tool-for-Product-Builders https://www.shortcut.com/blog/alternatives-to-height-app/ https://productgrowth.in/tools/product-management/height/

Sheet Enterprise Features
A1: Enterprise Features
A3: Platform | B3: Category | C3: Status | D3: SSO/SAML | E3: SCIM/user provisioning | F3: RBAC | G3: Granular permissions | H3: Audit logs | I3: Data residency | J3: SOC 2 | K3: ISO 27001 | L3: HIPAA/regulated support | M3: Encryption | N3: Admin console | O3: Retention/legal hold | P3: eDiscovery | Q3: IP allowlisting | R3: On-prem/self-hosted option | S3: Published uptime/SLA | T3: Notes / Evidence URLs
A4: Jira Software | B4: Traditional Issue Tracking / Agile | C4: Active | D4: 3 | E4: 3 | F4: 3 | G4: 3 | H4: 3 | I4: 3 | J4: 3 | K4: 3 | L4: 2 | M4: 3 | N4: 3 | O4: 2 | P4: 2 | Q4: 3 | R4: 3 | S4: 3 | T4: https://www.atlassian.com/software/jira/features https://www.atlassian.com/roadmap/cloud https://confluence.atlassian.com/cloud/blog
A5: Azure DevOps Boards | B5: Traditional Issue Tracking / Agile | C5: Active | D5: 3 | E5: 3 | F5: 3 | G5: 3 | H5: 3 | I5: 3 | J5: 3 | K5: 3 | L5: 2 | M5: 3 | N5: 3 | O5: 2 | P5: 2 | Q5: 3 | R5: 3 | S5: 3 | T5: https://azure.microsoft.com/en-us/products/devops/boards https://learn.microsoft.com/en-us/azure/devops/boards/get-started/what-is-azure-boards?view=azure-devops https://learn.microsoft.com/en-us/azure/devops/boards/work-items/about-work-items?view=azure-devops
A6: GitHub Projects | B6: Developer-Native | C6: Active | D6: 2 | E6: 2 | F6: 2 | G6: 2 | H6: 2 | I6: 2 | J6: 2 | K6: 2 | L6: 1 | M6: 2 | N6: 2 | O6: 1 | P6: 1 | Q6: 2 | R6: 2 | S6: 2 | T6: https://github.com/features/issues https://docs.github.com/issues/planning-and-tracking-with-projects/learning-about-projects/about-projects https://docs.github.com/en/issues/planning-and-tracking-with-projects
A7: Linear | B7: Developer-Native | C7: Active | D7: 2 | E7: 2 | F7: 2 | G7: 2 | H7: 2 | I7: 2 | J7: 2 | K7: 2 | L7: 1 | M7: 2 | N7: 2 | O7: 1 | P7: 1 | Q7: 2 | R7: 2 | S7: 2 | T7: https://linear.app/ https://linear.app/plan https://linear.app/integrations
A8: GitLab Plan | B8: Developer-Native / DevSecOps | C8: Active | D8: 3 | E8: 3 | F8: 3 | G8: 3 | H8: 3 | I8: 3 | J8: 3 | K8: 3 | L8: 2 | M8: 3 | N8: 3 | O8: 2 | P8: 2 | Q8: 3 | R8: 3 | S8: 3 | T8: https://docs.gitlab.com/user/group/epics/ https://docs.gitlab.com/user/group/roadmap/ https://about.gitlab.com/features/
A9: Asana | B9: General Work Management | C9: Active | D9: 3 | E9: 3 | F9: 3 | G9: 3 | H9: 3 | I9: 3 | J9: 3 | K9: 3 | L9: 2 | M9: 3 | N9: 3 | O9: 2 | P9: 2 | Q9: 3 | R9: 3 | S9: 3 | T9: https://asana.com/features https://asana.com/product/ai https://help.asana.com/s/article/learn-about-asana-advanced-features
A10: monday work management | B10: General Work Management | C10: Active | D10: 3 | E10: 3 | F10: 3 | G10: 3 | H10: 3 | I10: 3 | J10: 3 | K10: 3 | L10: 2 | M10: 3 | N10: 3 | O10: 2 | P10: 2 | Q10: 3 | R10: 3 | S10: 3 | T10: https://monday.com/ https://monday.com/work-management https://monday.com/features/automations
A11: ClickUp | B11: General Work Management | C11: Active | D11: 2 | E11: 2 | F11: 2 | G11: 2 | H11: 2 | I11: 2 | J11: 2 | K11: 2 | L11: 1 | M11: 2 | N11: 2 | O11: 1 | P11: 1 | Q11: 2 | R11: 2 | S11: 2 | T11: https://clickup.com/ https://clickup.com/features https://clickup.com/blog/ai-workflow-automation/
A12: Trello | B12: Kanban / Lightweight Work Management | C12: Active | D12: 2 | E12: 2 | F12: 2 | G12: 2 | H12: 2 | I12: 2 | J12: 2 | K12: 2 | L12: 1 | M12: 2 | N12: 2 | O12: 1 | P12: 1 | Q12: 2 | R12: 2 | S12: 2 | T12: https://trello.com/power-ups https://trello.com/pricing https://trello.com/enterprise
A13: Wrike | B13: General Work Management / Enterprise | C13: Active | D13: 3 | E13: 3 | F13: 3 | G13: 3 | H13: 3 | I13: 3 | J13: 3 | K13: 3 | L13: 2 | M13: 3 | N13: 3 | O13: 2 | P13: 2 | Q13: 3 | R13: 3 | S13: 3 | T13: https://www.wrike.com/features/ https://www.wrike.com/ https://www.wrike.com/features/work-intelligence/
A14: Smartsheet | B14: Work Management / PMO | C14: Active | D14: 3 | E14: 3 | F14: 3 | G14: 3 | H14: 3 | I14: 3 | J14: 3 | K14: 3 | L14: 2 | M14: 3 | N14: 3 | O14: 2 | P14: 2 | Q14: 3 | R14: 3 | S14: 3 | T14: https://www.smartsheet.com/platform/features https://www.smartsheet.com/solutions/project-management https://www.smartsheet.com/
A15: Airtable | B15: Database-Centric Work Platform | C15: Active | D15: 3 | E15: 3 | F15: 3 | G15: 3 | H15: 3 | I15: 3 | J15: 3 | K15: 3 | L15: 2 | M15: 3 | N15: 3 | O15: 2 | P15: 2 | Q15: 3 | R15: 3 | S15: 3 | T15: https://www.airtable.com/ https://www.airtable.com/platform/ai https://support.airtable.com/docs/using-omni-ai-in-airtable
... A38: Height | B38: AI-Native / Discontinued | C38: Discontinued Sep 2025 | D38: 1 | E38: 1 | F38: 1 | G38: 1 | H38: 1 | I38: 1 | J38: 1 | K38: 1 | L38: 0 | M38: 1 | N38: 1 | O38: 0 | P38: 0 | Q38: 1 | R38: 1 | S38: 0 | T38: https://www.businesswire.com/news/home/20241008197812/en/Height.app-Unveils-First-Ever-Autonomous-Project-Collaboration-Tool-for-Product-Builders https://www.shortcut.com/blog/alternatives-to-height-app/ https://productgrowth.in/tools/product-management/height/

Sheet AI Capabilities
A1: AI Capabilities
A3: Platform | B3: Category | C3: Status | D3: AI writing/summarization | E3: AI task creation | F3: AI project generation | G3: AI prioritization | H3: AI scheduling | I3: Risk prediction | J3: AI search/Q&A | K3: AI workflow builder | L3: Configurable AI agents | M3: Meeting notes to tasks | N3: Automated status updates | O3: Human/agent resource planning | P3: AI governance/admin controls | Q3: Notes / Evidence URLs
A4: Jira Software | B4: Traditional Issue Tracking / Agile | C4: Active | D4: 2 | E4: 2 | F4: 1 | G4: 2 | H4: 2 | I4: 2 | J4: 2 | K4: 2 | L4: 2 | M4: 2 | N4: 2 | O4: 1 | P4: 2 | Q4: https://www.atlassian.com/software/jira/features https://www.atlassian.com/roadmap/cloud https://confluence.atlassian.com/cloud/blog
A5: Azure DevOps Boards | B5: Traditional Issue Tracking / Agile | C5: Active | D5: 1 | E5: 1 | F5: 1 | G5: 1 | H5: 1 | I5: 1 | J5: 1 | K5: 1 | L5: 0 | M5: 1 | N5: 1 | O5: 0 | P5: 1 | Q5: https://azure.microsoft.com/en-us/products/devops/boards https://learn.microsoft.com/en-us/azure/devops/boards/get-started/what-is-azure-boards?view=azure-devops https://learn.microsoft.com/en-us/azure/devops/boards/work-items/about-work-items?view=azure-devops
A6: GitHub Projects | B6: Developer-Native | C6: Active | D6: 2 | E6: 2 | F6: 2 | G6: 2 | H6: 2 | I6: 2 | J6: 2 | K6: 2 | L6: 1 | M6: 2 | N6: 2 | O6: 1 | P6: 2 | Q6: https://github.com/features/issues https://docs.github.com/issues/planning-and-tracking-with-projects/learning-about-projects/about-projects https://docs.github.com/en/issues/planning-and-tracking-with-projects
A7: Linear | B7: Developer-Native | C7: Active | D7: 3 | E7: 3 | F7: 3 | G7: 3 | H7: 1 | I7: 3 | J7: 3 | K7: 3 | L7: 2 | M7: 3 | N7: 3 | O7: 2 | P7: 3 | Q7: https://linear.app/ https://linear.app/plan https://linear.app/integrations
A8: GitLab Plan | B8: Developer-Native / DevSecOps | C8: Active | D8: 2 | E8: 2 | F8: 2 | G8: 2 | H8: 2 | I8: 2 | J8: 2 | K8: 2 | L8: 1 | M8: 2 | N8: 2 | O8: 1 | P8: 2 | Q8: https://docs.gitlab.com/user/group/epics/ https://docs.gitlab.com/user/group/roadmap/ https://about.gitlab.com/features/
A9: Asana | B9: General Work Management | C9: Active | D9: 3 | E9: 3 | F9: 3 | G9: 3 | H9: 3 | I9: 3 | J9: 3 | K9: 3 | L9: 3 | M9: 3 | N9: 3 | O9: 2 | P9: 3 | Q9: https://asana.com/features https://asana.com/product/ai https://help.asana.com/s/article/learn-about-asana-advanced-features
A10: monday work management | B10: General Work Management | C10: Active | D10: 2 | E10: 2 | F10: 2 | G10: 2 | H10: 2 | I10: 2 | J10: 2 | K10: 2 | L10: 1 | M10: 2 | N10: 2 | O10: 1 | P10: 2 | Q10: https://monday.com/ https://monday.com/work-management https://monday.com/features/automations
A11: ClickUp | B11: General Work Management | C11: Active | D11: 3 | E11: 3 | F11: 3 | G11: 3 | H11: 3 | I11: 3 | J11: 3 | K11: 3 | L11: 2 | M11: 3 | N11: 3 | O11: 2 | P11: 3 | Q11: https://clickup.com/ https://clickup.com/features https://clickup.com/blog/ai-workflow-automation/
A12: Trello | B12: Kanban / Lightweight Work Management | C12: Active | D12: 1 | E12: 1 | F12: 1 | G12: 1 | H12: 1 | I12: 1 | J12: 1 | K12: 1 | L12: 0 | M12: 1 | N12: 1 | O12: 0 | P12: 1 | Q12: https://trello.com/power-ups https://trello.com/pricing https://trello.com/enterprise
A13: Wrike | B13: General Work Management / Enterprise | C13: Active | D13: 3 | E13: 3 | F13: 3 | G13: 3 | H13: 3 | I13: 3 | J13: 3 | K13: 3 | L13: 2 | M13: 3 | N13: 3 | O13: 2 | P13: 3 | Q13: https://www.wrike.com/features/ https://www.wrike.com/ https://www.wrike.com/features/work-intelligence/
A14: Smartsheet | B14: Work Management / PMO | C14: Active | D14: 2 | E14: 2 | F14: 2 | G14: 2 | H14: 2 | I14: 2 | J14: 2 | K14: 2 | L14: 1 | M14: 2 | N14: 2 | O14: 1 | P14: 2 | Q14: https://www.smartsheet.com/platform/features https://www.smartsheet.com/solutions/project-management https://www.smartsheet.com/
A15: Airtable | B15: Database-Centric Work Platform | C15: Active | D15: 3 | E15: 3 | F15: 3 | G15: 3 | H15: 3 | I15: 3 | J15: 3 | K15: 3 | L15: 2 | M15: 3 | N15: 3 | O15: 2 | P15: 3 | Q15: https://www.airtable.com/ https://www.airtable.com/platform/ai https://support.airtable.com/docs/using-omni-ai-in-airtable
... A38: Height | B38: AI-Native / Discontinued | C38: Discontinued Sep 2025 | D38: 3 | E38: 3 | F38: 2 | G38: 3 | H38: 2 | I38: 2 | J38: 2 | K38: 2 | L38: 2 | M38: 2 | N38: 3 | O38: 2 | P38: 2 | Q38: https://www.businesswire.com/news/home/20241008197812/en/Height.app-Unveils-First-Ever-Autonomous-Project-Collaboration-Tool-for-Product-Builders https://www.shortcut.com/blog/alternatives-to-height-app/ https://productgrowth.in/tools/product-management/height/

Sheet Integration Matrix
A1: Integration Matrix
A3: Platform | B3: Category | C3: Status | D3: GitHub integration | E3: GitLab integration | F3: Bitbucket integration | G3: Pull request links | H3: Commit links | I3: Branch linking/automation | J3: CI/CD integration | K3: Release management | L3: REST API | M3: GraphQL API | N3: CLI or SDK | O3: Webhooks | P3: Repository browsing | Q3: Slack integration | R3: Microsoft Teams integration | S3: Email integration | T3: Google Workspace | U3: Microsoft 365 | V3: Zapier | W3: Make | X3: n8n | Y3: Marketplace/apps | Z3: Plugin/extensions | AA3: BI/data export | AB3: Notes / Evidence URLs
A4: Jira Software | B4: Traditional Issue Tracking / Agile | C4: Active | D4: 3 | E4: 3 | F4: 3 | G4: 3 | H4: 3 | I4: 3 | J4: 3 | K4: 3 | L4: 3 | M4: 2 | N4: 3 | O4: 3 | P4: 3 | Q4: 3 | R4: 3 | S4: 3 | T4: 3 | U4: 3 | V4: 3 | W4: 3 | X4: 3 | Y4: 3 | Z4: 3 | AA4: 3 | AB4: https://www.atlassian.com/software/jira/features https://www.atlassian.com/roadmap/cloud https://confluence.atlassian.com/cloud/blog
A5: Azure DevOps Boards | B5: Traditional Issue Tracking / Agile | C5: Active | D5: 3 | E5: 3 | F5: 3 | G5: 3 | H5: 3 | I5: 3 | J5: 3 | K5: 3 | L5: 3 | M5: 0 | N5: 3 | O5: 3 | P5: 3 | Q5: 3 | R5: 2 | S5: 3 | T5: 2 | U5: 2 | V5: 2 | W5: 2 | X5: 2 | Y5: 2 | Z5: 2 | AA5: 2 | AB5: https://azure.microsoft.com/en-us/products/devops/boards https://learn.microsoft.com/en-us/azure/devops/boards/get-started/what-is-azure-boards?view=azure-devops https://learn.microsoft.com/en-us/azure/devops/boards/work-items/about-work-items?view=azure-devops
A6: GitHub Projects | B6: Developer-Native | C6: Active | D6: 3 | E6: 3 | F6: 3 | G6: 3 | H6: 3 | I6: 3 | J6: 3 | K6: 3 | L6: 3 | M6: 3 | N6: 3 | O6: 3 | P6: 3 | Q6: 3 | R6: 3 | S6: 3 | T6: 3 | U6: 3 | V6: 3 | W6: 3 | X6: 3 | Y6: 3 | Z6: 3 | AA6: 3 | AB6: https://github.com/features/issues https://docs.github.com/issues/planning-and-tracking-with-projects/learning-about-projects/about-projects https://docs.github.com/en/issues/planning-and-tracking-with-projects
A7: Linear | B7: Developer-Native | C7: Active | D7: 3 | E7: 3 | F7: 3 | G7: 3 | H7: 3 | I7: 3 | J7: 3 | K7: 3 | L7: 3 | M7: 3 | N7: 3 | O7: 3 | P7: 3 | Q7: 3 | R7: 3 | S7: 3 | T7: 3 | U7: 3 | V7: 3 | W7: 3 | X7: 3 | Y7: 3 | Z7: 3 | AA7: 3 | AB7: https://linear.app/ https://linear.app/plan https://linear.app/integrations
A8: GitLab Plan | B8: Developer-Native / DevSecOps | C8: Active | D8: 3 | E8: 3 | F8: 3 | G8: 3 | H8: 3 | I8: 3 | J8: 3 | K8: 3 | L8: 3 | M8: 3 | N8: 3 | O8: 3 | P8: 3 | Q8: 3 | R8: 2 | S8: 3 | T8: 2 | U8: 2 | V8: 2 | W8: 2 | X8: 2 | Y8: 2 | Z8: 2 | AA8: 2 | AB8: https://docs.gitlab.com/user/group/epics/ https://docs.gitlab.com/user/group/roadmap/ https://about.gitlab.com/features/
A9: Asana | B9: General Work Management | C9: Active | D9: 1 | E9: 1 | F9: 1 | G9: 1 | H9: 1 | I9: 1 | J9: 1 | K9: 1 | L9: 2 | M9: 0 | N9: 1 | O9: 1 | P9: 0 | Q9: 3 | R9: 3 | S9: 3 | T9: 3 | U9: 3 | V9: 3 | W9: 3 | X9: 3 | Y9: 3 | Z9: 3 | AA9: 3 | AB9: https://asana.com/features https://asana.com/product/ai https://help.asana.com/s/article/learn-about-asana-advanced-features
A10: monday work management | B10: General Work Management | C10: Active | D10: 1 | E10: 1 | F10: 1 | G10: 1 | H10: 1 | I10: 1 | J10: 1 | K10: 1 | L10: 2 | M10: 3 | N10: 1 | O10: 1 | P10: 0 | Q10: 3 | R10: 3 | S10: 3 | T10: 3 | U10: 3 | V10: 3 | W10: 3 | X10: 3 | Y10: 3 | Z10: 3 | AA10: 3 | AB10: https://monday.com/ https://monday.com/work-management https://monday.com/features/automations
A11: ClickUp | B11: General Work Management | C11: Active | D11: 2 | E11: 2 | F11: 2 | G11: 2 | H11: 2 | I11: 2 | J11: 2 | K11: 2 | L11: 3 | M11: 0 | N11: 2 | O11: 2 | P11: 0 | Q11: 3 | R11: 3 | S11: 3 | T11: 3 | U11: 3 | V11: 3 | W11: 3 | X11: 3 | Y11: 3 | Z11: 3 | AA11: 3 | AB11: https://clickup.com/ https://clickup.com/features https://clickup.com/blog/ai-workflow-automation/
A12: Trello | B12: Kanban / Lightweight Work Management | C12: Active | D12: 1 | E12: 1 | F12: 1 | G12: 1 | H12: 1 | I12: 1 | J12: 1 | K12: 1 | L12: 2 | M12: 0 | N12: 1 | O12: 1 | P12: 1 | Q12: 3 | R12: 3 | S12: 3 | T12: 3 | U12: 3 | V12: 3 | W12: 3 | X12: 3 | Y12: 3 | Z12: 3 | AA12: 3 | AB12: https://trello.com/power-ups https://trello.com/pricing https://trello.com/enterprise
A13: Wrike | B13: General Work Management / Enterprise | C13: Active | D13: 1 | E13: 1 | F13: 1 | G13: 1 | H13: 1 | I13: 1 | J13: 1 | K13: 1 | L13: 2 | M13: 0 | N13: 1 | O13: 1 | P13: 0 | Q13: 3 | R13: 3 | S13: 3 | T13: 3 | U13: 3 | V13: 3 | W13: 3 | X13: 3 | Y13: 3 | Z13: 3 | AA13: 3 | AB13: https://www.wrike.com/features/ https://www.wrike.com/ https://www.wrike.com/features/work-intelligence/
A14: Smartsheet | B14: Work Management / PMO | C14: Active | D14: 1 | E14: 1 | F14: 1 | G14: 1 | H14: 1 | I14: 1 | J14: 1 | K14: 1 | L14: 2 | M14: 0 | N14: 1 | O14: 1 | P14: 0 | Q14: 3 | R14: 3 | S14: 3 | T14: 3 | U14: 3 | V14: 3 | W14: 3 | X14: 3 | Y14: 3 | Z14: 3 | AA14: 3 | AB14: https://www.smartsheet.com/platform/features https://www.smartsheet.com/solutions/project-management https://www.smartsheet.com/
A15: Airtable | B15: Database-Centric Work Platform | C15: Active | D15: 1 | E15: 1 | F15: 1 | G15: 1 | H15: 1 | I15: 1 | J15: 1 | K15: 1 | L15: 2 | M15: 0 | N15: 1 | O15: 1 | P15: 1 | Q15: 3 | R15: 3 | S15: 3 | T15: 3 | U15: 3 | V15: 3 | W15: 3 | X15: 3 | Y15: 3 | Z15: 3 | AA15: 3 | AB15: https://www.airtable.com/ https://www.airtable.com/platform/ai https://support.airtable.com/docs/using-omni-ai-in-airtable
... A38: Height | B38: AI-Native / Discontinued | C38: Discontinued Sep 2025 | D38: 2 | E38: 2 | F38: 2 | G38: 2 | H38: 2 | I38: 2 | J38: 2 | K38: 2 | L38: 2 | M38: 1 | N38: 2 | O38: 2 | P38: 2 | Q38: 2 | R38: 1 | S38: 2 | T38: 1 | U38: 1 | V38: 1 | W38: 1 | X38: 1 | Y38: 1 | Z38: 1 | AA38: 1 | AB38: https://www.businesswire.com/news/home/20241008197812/en/Height.app-Unveils-First-Ever-Autonomous-Project-Collaboration-Tool-for-Product-Builders https://www.shortcut.com/blog/alternatives-to-height-app/ https://productgrowth.in/tools/product-management/height/

Sheet Scoring
A1: Scoring
A2: Formula-driven category scores. Each category is average(score)/3*100; Overall uses category weights; edit Feature Matrix scores to recalculate.
D3: Weights -> | E3: 1.1 | F3: 1.1 | G3: 1 | H3: 1.05 | I3: 0.9 | J3: 1 | K3: 1.05 | L3: 0.9 | M3: 0.9 | N3: 1
A4: Platform | B4: Primary Category | C4: Overall Score | D4: Rank | E4: Core Work Items | F4: Planning & Views | G4: Agile & Product | H4: Workflow & Automation | I4: Collaboration & Knowledge | J4: Reporting & Analytics | K4: Enterprise & Security | L4: Developer & DevOps | M4: Integrations & Extensibility | N4: AI & Agentic
A5: Jira Software | B5: Traditional Issue Tracking / Agile | C5: =ROUND(SUMPRODUCT(E5:N5,$E$3:$N$3)/SUM($E$3:$N$3),1) -> 90.5 | D5: =RANK(C5,$C$5:$C$39,0) -> 2 | E5: =ROUND(AVERAGE('Feature Matrix'!$F5:$S5)/3*100,1) -> 100 | F5: =ROUND(AVERAGE('Feature Matrix'!$T5:$AI5)/3*100,1) -> 93.8 | G5: =ROUND(AVERAGE('Feature Matrix'!$AJ5:$AW5)/3*100,1) -> 97.6 | H5: =ROUND(AVERAGE('Feature Matrix'!$AX5:$BL5)/3*100,1) -> 100 | I5: =ROUND(AVERAGE('Feature Matrix'!$BM5:$BZ5)/3*100,1) -> 57.1 | J5: =ROUND(AVERAGE('Feature Matrix'!$CA5:$CN5)/3*100,1) -> 100 | K5: =ROUND(AVERAGE('Feature Matrix'!$CO5:$DD5)/3*100,1) -> 93.8 | L5: =ROUND(AVERAGE('Feature Matrix'!$DE5:$DQ5)/3*100,1) -> 97.4 | M5: =ROUND(AVERAGE('Feature Matrix'!$DR5:$EB5)/3*100,1) -> 100 | N5: =ROUND(AVERAGE('Feature Matrix'!$EC5:$EO5)/3*100,1) -> 61.5
A6: Azure DevOps Boards | B6: Traditional Issue Tracking / Agile | C6: =ROUND(SUMPRODUCT(E6:N6,$E$3:$N$3)/SUM($E$3:$N$3),1) -> 84.2 | D6: =RANK(C6,$C$5:$C$39,0) -> 7 | E6: =ROUND(AVERAGE('Feature Matrix'!$F6:$S6)/3*100,1) -> 100 | F6: =ROUND(AVERAGE('Feature Matrix'!$T6:$AI6)/3*100,1) -> 93.8 | G6: =ROUND(AVERAGE('Feature Matrix'!$AJ6:$AW6)/3*100,1) -> 97.6 | H6: =ROUND(AVERAGE('Feature Matrix'!$AX6:$BL6)/3*100,1) -> 100 | I6: =ROUND(AVERAGE('Feature Matrix'!$BM6:$BZ6)/3*100,1) -> 57.1 | J6: =ROUND(AVERAGE('Feature Matrix'!$CA6:$CN6)/3*100,1) -> 100 | K6: =ROUND(AVERAGE('Feature Matrix'!$CO6:$DD6)/3*100,1) -> 93.8 | L6: =ROUND(AVERAGE('Feature Matrix'!$DE6:$DQ6)/3*100,1) -> 92.3 | M6: =ROUND(AVERAGE('Feature Matrix'!$DR6:$EB6)/3*100,1) -> 72.7 | N6: =ROUND(AVERAGE('Feature Matrix'!$EC6:$EO6)/3*100,1) -> 28.2
A7: GitHub Projects | B7: Developer-Native | C7: =ROUND(SUMPRODUCT(E7:N7,$E$3:$N$3)/SUM($E$3:$N$3),1) -> 69.6 | D7: =RANK(C7,$C$5:$C$39,0) -> 24 | E7: =ROUND(AVERAGE('Feature Matrix'!$F7:$S7)/3*100,1) -> 78.6 | F7: =ROUND(AVERAGE('Feature Matrix'!$T7:$AI7)/3*100,1) -> 47.9 | G7: =ROUND(AVERAGE('Feature Matrix'!$AJ7:$AW7)/3*100,1) -> 64.3 | H7: =ROUND(AVERAGE('Feature Matrix'!$AX7:$BL7)/3*100,1) -> 66.7 | I7: =ROUND(AVERAGE('Feature Matrix'!$BM7:$BZ7)/3*100,1) -> 61.9 | J7: =ROUND(AVERAGE('Feature Matrix'!$CA7:$CN7)/3*100,1) -> 61.9 | K7: =ROUND(AVERAGE('Feature Matrix'!$CO7:$DD7)/3*100,1) -> 60.4 | L7: =ROUND(AVERAGE('Feature Matrix'!$DE7:$DQ7)/3*100,1) -> 100 | M7: =ROUND(AVERAGE('Feature Matrix'!$DR7:$EB7)/3*100,1) -> 100 | N7: =ROUND(AVERAGE('Feature Matrix'!$EC7:$EO7)/3*100,1) -> 61.5
A8: Linear | B8: Developer-Native | C8: =ROUND(SUMPRODUCT(E8:N8,$E$3:$N$3)/SUM($E$3:$N$3),1) -> 78.8 | D8: =RANK(C8,$C$5:$C$39,0) -> 13 | E8: =ROUND(AVERAGE('Feature Matrix'!$F8:$S8)/3*100,1) -> 100 | F8: =ROUND(AVERAGE('Feature Matrix'!$T8:$AI8)/3*100,1) -> 54.2 | G8: =ROUND(AVERAGE('Feature Matrix'!$AJ8:$AW8)/3*100,1) -> 97.6 | H8: =ROUND(AVERAGE('Feature Matrix'!$AX8:$BL8)/3*100,1) -> 66.7 | I8: =ROUND(AVERAGE('Feature Matrix'!$BM8:$BZ8)/3*100,1) -> 61.9 | J8: =ROUND(AVERAGE('Feature Matrix'!$CA8:$CN8)/3*100,1) -> 61.9 | K8: =ROUND(AVERAGE('Feature Matrix'!$CO8:$DD8)/3*100,1) -> 60.4 | L8: =ROUND(AVERAGE('Feature Matrix'!$DE8:$DQ8)/3*100,1) -> 100 | M8: =ROUND(AVERAGE('Feature Matrix'!$DR8:$EB8)/3*100,1) -> 100 | N8: =ROUND(AVERAGE('Feature Matrix'!$EC8:$EO8)/3*100,1) -> 89.7
A9: GitLab Plan | B9: Developer-Native / DevSecOps | C9: =ROUND(SUMPRODUCT(E9:N9,$E$3:$N$3)/SUM($E$3:$N$3),1) -> 83.8 | D9: =RANK(C9,$C$5:$C$39,0) -> 8 | E9: =ROUND(AVERAGE('Feature Matrix'!$F9:$S9)/3*100,1) -> 100 | F9: =ROUND(AVERAGE('Feature Matrix'!$T9:$AI9)/3*100,1) -> 81.3 | G9: =ROUND(AVERAGE('Feature Matrix'!$AJ9:$AW9)/3*100,1) -> 97.6 | H9: =ROUND(AVERAGE('Feature Matrix'!$AX9:$BL9)/3*100,1) -> 66.7 | I9: =ROUND(AVERAGE('Feature Matrix'!$BM9:$BZ9)/3*100,1) -> 61.9 | J9: =ROUND(AVERAGE('Feature Matrix'!$CA9:$CN9)/3*100,1) -> 100 | K9: =ROUND(AVERAGE('Feature Matrix'!$CO9:$DD9)/3*100,1) -> 93.8 | L9: =ROUND(AVERAGE('Feature Matrix'!$DE9:$DQ9)/3*100,1) -> 100 | M9: =ROUND(AVERAGE('Feature Matrix'!$DR9:$EB9)/3*100,1) -> 72.7 | N9: =ROUND(AVERAGE('Feature Matrix'!$EC9:$EO9)/3*100,1) -> 61.5
A10: Asana | B10: General Work Management | C10: =ROUND(SUMPRODUCT(E10:N10,$E$3:$N$3)/SUM($E$3:$N$3),1) -> 87.9 | D10: =RANK(C10,$C$5:$C$39,0) -> 5 | E10: =ROUND(AVERAGE('Feature Matrix'!$F10:$S10)/3*100,1) -> 100 | F10: =ROUND(AVERAGE('Feature Matrix'!$T10:$AI10)/3*100,1) -> 93.8 | G10: =ROUND(AVERAGE('Feature Matrix'!$AJ10:$AW10)/3*100,1) -> 57.1 | H10: =ROUND(AVERAGE('Feature Matrix'!$AX10:$BL10)/3*100,1) -> 100 | I10: =ROUND(AVERAGE('Feature Matrix'!$BM10:$BZ10)/3*100,1) -> 100 | J10: =ROUND(AVERAGE('Feature Matrix'!$CA10:$CN10)/3*100,1) -> 100 | K10: =ROUND(AVERAGE('Feature Matrix'!$CO10:$DD10)/3*100,1) -> 93.8 | L10: =ROUND(AVERAGE('Feature Matrix'!$DE10:$DQ10)/3*100,1) -> 30.8 | M10: =ROUND(AVERAGE('Feature Matrix'!$DR10:$EB10)/3*100,1) -> 100 | N10: =ROUND(AVERAGE('Feature Matrix'!$EC10:$EO10)/3*100,1) -> 97.4
A11: monday work management | B11: General Work Management | C11: =ROUND(SUMPRODUCT(E11:N11,$E$3:$N$3)/SUM($E$3:$N$3),1) -> 82.2 | D11: =RANK(C11,$C$5:$C$39,0) -> 11 | E11: =ROUND(AVERAGE('Feature Matrix'!$F11:$S11)/3*100,1) -> 100 | F11: =ROUND(AVERAGE('Feature Matrix'!$T11:$AI11)/3*100,1) -> 95.8 | G11: =ROUND(AVERAGE('Feature Matrix'!$AJ11:$AW11)/3*100,1) -> 57.1 | H11: =ROUND(AVERAGE('Feature Matrix'!$AX11:$BL11)/3*100,1) -> 100 | I11: =ROUND(AVERAGE('Feature Matrix'!$BM11:$BZ11)/3*100,1) -> 66.7 | J11: =ROUND(AVERAGE('Feature Matrix'!$CA11:$CN11)/3*100,1) -> 100 | K11: =ROUND(AVERAGE('Feature Matrix'!$CO11:$DD11)/3*100,1) -> 93.8 | L11: =ROUND(AVERAGE('Feature Matrix'!$DE11:$DQ11)/3*100,1) -> 38.5 | M11: =ROUND(AVERAGE('Feature Matrix'!$DR11:$EB11)/3*100,1) -> 100 | N11: =ROUND(AVERAGE('Feature Matrix'!$EC11:$EO11)/3*100,1) -> 61.5
A12: ClickUp | B12: General Work Management | C12: =ROUND(SUMPRODUCT(E12:N12,$E$3:$N$3)/SUM($E$3:$N$3),1) -> 90.7 | D12: =RANK(C12,$C$5:$C$39,0) -> 1 | E12: =ROUND(AVERAGE('Feature Matrix'!$F12:$S12)/3*100,1) -> 100 | F12: =ROUND(AVERAGE('Feature Matrix'!$T12:$AI12)/3*100,1) -> 95.8 | G12: =ROUND(AVERAGE('Feature Matrix'!$AJ12:$AW12)/3*100,1) -> 95.2 | H12: =ROUND(AVERAGE('Feature Matrix'!$AX12:$BL12)/3*100,1) -> 100 | I12: =ROUND(AVERAGE('Feature Matrix'!$BM12:$BZ12)/3*100,1) -> 100 | J12: =ROUND(AVERAGE('Feature Matrix'!$CA12:$CN12)/3*100,1) -> 100 | K12: =ROUND(AVERAGE('Feature Matrix'!$CO12:$DD12)/3*100,1) -> 60.4 | L12: =ROUND(AVERAGE('Feature Matrix'!$DE12:$DQ12)/3*100,1) -> 59 | M12: =ROUND(AVERAGE('Feature Matrix'!$DR12:$EB12)/3*100,1) -> 100 | N12: =ROUND(AVERAGE('Feature Matrix'!$EC12:$EO12)/3*100,1) -> 94.9
A13: Trello | B13: Kanban / Lightweight Work Management | C13: =ROUND(SUMPRODUCT(E13:N13,$E$3:$N$3)/SUM($E$3:$N$3),1) -> 51.5 | D13: =RANK(C13,$C$5:$C$39,0) -> 31 | E13: =ROUND(AVERAGE('Feature Matrix'!$F13:$S13)/3*100,1) -> 78.6 | F13: =ROUND(AVERAGE('Feature Matrix'!$T13:$AI13)/3*100,1) -> 27.1 | G13: =ROUND(AVERAGE('Feature Matrix'!$AJ13:$AW13)/3*100,1) -> 23.8 | H13: =ROUND(AVERAGE('Feature Matrix'!$AX13:$BL13)/3*100,1) -> 66.7 | I13: =ROUND(AVERAGE('Feature Matrix'!$BM13:$BZ13)/3*100,1) -> 66.7 | J13: =ROUND(AVERAGE('Feature Matrix'!$CA13:$CN13)/3*100,1) -> 33.3 | K13: =ROUND(AVERAGE('Feature Matrix'!$CO13:$DD13)/3*100,1) -> 60.4 | L13: =ROUND(AVERAGE('Feature Matrix'!$DE13:$DQ13)/3*100,1) -> 33.3 | M13: =ROUND(AVERAGE('Feature Matrix'!$DR13:$EB13)/3*100,1) -> 100 | N13: =ROUND(AVERAGE('Feature Matrix'!$EC13:$EO13)/3*100,1) -> 28.2
A14: Wrike | B14: General Work Management / Enterprise | C14: =ROUND(SUMPRODUCT(E14:N14,$E$3:$N$3)/SUM($E$3:$N$3),1) -> 88.6 | D14: =RANK(C14,$C$5:$C$39,0) -> 4 | E14: =ROUND(AVERAGE('Feature Matrix'!$F14:$S14)/3*100,1) -> 100 | F14: =ROUND(AVERAGE('Feature Matrix'!$T14:$AI14)/3*100,1) -> 95.8 | G14: =ROUND(AVERAGE('Feature Matrix'!$AJ14:$AW14)/3*100,1) -> 64.3 | H14: =ROUND(AVERAGE('Feature Matrix'!$AX14:$BL14)/3*100,1) -> 100 | I14: =ROUND(AVERAGE('Feature Matrix'!$BM14:$BZ14)/3*100,1) -> 100 | J14: =ROUND(AVERAGE('Feature Matrix'!$CA14:$CN14)/3*100,1) -> 100 | K14: =ROUND(AVERAGE('Feature Matrix'!$CO14:$DD14)/3*100,1) -> 93.8 | L14: =ROUND(AVERAGE('Feature Matrix'!$DE14:$DQ14)/3*100,1) -> 30.8 | M14: =ROUND(AVERAGE('Feature Matrix'!$DR14:$EB14)/3*100,1) -> 100 | N14: =ROUND(AVERAGE('Feature Matrix'!$EC14:$EO14)/3*100,1) -> 94.9
A15: Smartsheet | B15: Work Management / PMO | C15: =ROUND(SUMPRODUCT(E15:N15,$E$3:$N$3)/SUM($E$3:$N$3),1) -> 81.3 | D15: =RANK(C15,$C$5:$C$39,0) -> 12 | E15: =ROUND(AVERAGE('Feature Matrix'!$F15:$S15)/3*100,1) -> 100 | F15: =ROUND(AVERAGE('Feature Matrix'!$T15:$AI15)/3*100,1) -> 95.8 | G15: =ROUND(AVERAGE('Feature Matrix'!$AJ15:$AW15)/3*100,1) -> 57.1 | H15: =ROUND(AVERAGE('Feature Matrix'!$AX15:$BL15)/3*100,1) -> 100 | I15: =ROUND(AVERAGE('Feature Matrix'!$BM15:$BZ15)/3*100,1) -> 64.3 | J15: =ROUND(AVERAGE('Feature Matrix'!$CA15:$CN15)/3*100,1) -> 100 | K15: =ROUND(AVERAGE('Feature Matrix'!$CO15:$DD15)/3*100,1) -> 93.8 | L15: =ROUND(AVERAGE('Feature Matrix'!$DE15:$DQ15)/3*100,1) -> 30.8 | M15: =ROUND(AVERAGE('Feature Matrix'!$DR15:$EB15)/3*100,1) -> 100 | N15: =ROUND(AVERAGE('Feature Matrix'!$EC15:$EO15)/3*100,1) -> 61.5
A16: Airtable | B16: Database-Centric Work Platform | C16: =ROUND(SUMPRODUCT(E16:N16,$E$3:$N$3)/SUM($E$3:$N$3),1) -> 74.5 | D16: =RANK(C16,$C$5:$C$39,0) -> 19 | E16: =ROUND(AVERAGE('Feature Matrix'!$F16:$S16)/3*100,1) -> 100 | F16: =ROUND(AVERAGE('Feature Matrix'!$T16:$AI16)/3*100,1) -> 58.3 | G16: =ROUND(AVERAGE('Feature Matrix'!$AJ16:$AW16)/3*100,1) -> 28.6 | H16: =ROUND(AVERAGE('Feature Matrix'!$AX16:$BL16)/3*100,1) -> 100 | I16: =ROUND(AVERAGE('Feature Matrix'!$BM16:$BZ16)/3*100,1) -> 66.7 | J16: =ROUND(AVERAGE('Feature Matrix'!$CA16:$CN16)/3*100,1) -> 64.3 | K16: =ROUND(AVERAGE('Feature Matrix'!$CO16:$DD16)/3*100,1) -> 93.8 | L16: =ROUND(AVERAGE('Feature Matrix'!$DE16:$DQ16)/3*100,1) -> 33.3 | M16: =ROUND(AVERAGE('Feature Matrix'!$DR16:$EB16)/3*100,1) -> 100 | N16: =ROUND(AVERAGE('Feature Matrix'!$EC16:$EO16)/3*100,1) -> 94.9
... A39: Height | B39: AI-Native / Discontinued | C39: =ROUND(SUMPRODUCT(E39:N39,$E$3:$N$3)/SUM($E$3:$N$3),1) -> 56.6 | D39: =RANK(C39,$C$5:$C$39,0) -> 29 | E39: =ROUND(AVERAGE('Feature Matrix'!$F39:$S39)/3*100,1) -> 66.7 | F39: =ROUND(AVERAGE('Feature Matrix'!$T39:$AI39)/3*100,1) -> 62.5 | G39: =ROUND(AVERAGE('Feature Matrix'!$AJ39:$AW39)/3*100,1) -> 64.3 | H39: =ROUND(AVERAGE('Feature Matrix'!$AX39:$BL39)/3*100,1) -> 66.7 | I39: =ROUND(AVERAGE('Feature Matrix'!$BM39:$BZ39)/3*100,1) -> 66.7 | J39: =ROUND(AVERAGE('Feature Matrix'!$CA39:$CN39)/3*100,1) -> 33.3 | K39: =ROUND(AVERAGE('Feature Matrix'!$CO39:$DD39)/3*100,1) -> 25 | L39: =ROUND(AVERAGE('Feature Matrix'!$DE39:$DQ39)/3*100,1) -> 64.1 | M39: =ROUND(AVERAGE('Feature Matrix'!$DR39:$EB39)/3*100,1) -> 39.4 | N39: =ROUND(AVERAGE('Feature Matrix'!$EC39:$EO39)/3*100,1) -> 76.9

Sheet Legend
A1: Legend and Feature Dictionary
A3: Score | B3: Meaning | C3: How to interpret
A4: 0 | B4: None / Unknown | C4: No meaningful native support found in public material, or not applicable.
A5: 1 | B5: Limited / Add-on | C5: Available only through workaround, marketplace app, integration, template, or narrow implementation.
A6: 2 | B6: Native / Standard | C6: Supported natively for common use cases, possibly plan-limited.
A7: 3 | B7: Advanced / Strong | C7: Mature native capability, broad coverage, or category-defining implementation.
A10: Feature Code | B10: Category | C10: Feature | D10: Weight
A11: CORE-01 | B11: Core Work Items | C11: Task/work item creation | D11: 1.1
A12: CORE-02 | B12: Core Work Items | C12: Issue/bug tracking | D12: 1.1
A13: CORE-03 | B13: Core Work Items | C13: Subtasks or child items | D13: 1.1
A14: CORE-04 | B14: Core Work Items | C14: Checklists | D14: 1.1
A15: CORE-05 | B15: Core Work Items | C15: Recurring tasks | D15: 1.1
A16: CORE-06 | B16: Core Work Items | C16: Custom fields | D16: 1.1
A17: CORE-07 | B17: Core Work Items | C17: Task templates | D17: 1.1
A18: CORE-08 | B18: Core Work Items | C18: Bulk edit | D18: 1.1
A19: CORE-09 | B19: Core Work Items | C19: Forms/intake | D19: 1.1
A20: CORE-10 | B20: Core Work Items | C20: Attachments | D20: 1.1
A21: CORE-11 | B21: Core Work Items | C21: Priority | D21: 1.1
A22: CORE-12 | B22: Core Work Items | C22: Labels/tags | D22: 1.1
